<?xml version="1.0"?>

<!--
Drake URDF of the Seeed Studio reBot Arm B601 DM (6-DOF Damiao-motor arm with the stock actuated
parallel gripper). Kinematics, joint limits and inertials come from the manufacturer's URDF in
https://github.com/Seeed-Projects/reBotArmController_ROS2 (reBot_B601_DM_with_gripper.urdf);
visual meshes are decimated OBJ conversions of the original STLs and collision geometry is a set
of tight convex primitives fitted to each link. See the package README for details.
-->

<robot xmlns:drake="http://drake.mit.edu" name="rebot_b601_dm_with_gripper">

  <material name="Black">
    <color rgba="0.15 0.15 0.15 1.0"/>
  </material>
  <material name="Silver">
    <color rgba="0.82 0.82 0.83 1.0"/>
  </material>
  <material name="NeonGreen">
    <color rgba="0.62 0.82 0.2 1.0"/>
  </material>

  <link name="base_link">
    <inertial>
      <origin rpy="0 0 0" xyz="-7.849E-06 -1.1531E-06 0.029841"/>
      <mass value="0.83660000"/>
      <inertia ixx="0.00133040" ixy="0.00000001" ixz="0.00000000" iyy="0.00213119" iyz="0.00000000" izz="0.00275877"/>
    </inertial>
    <visual>
      <geometry>
        <mesh filename="package://rebot_b601_dm_description/meshes/links/visual/base_link.obj"/>
      </geometry>
      <origin rpy="0 0 0" xyz="0 0 0"/>
      <material name="Black"/>
    </visual>
    <collision>
      <geometry>
        <mesh filename="package://rebot_b601_dm_description/meshes/links/collision/base_link/base_link_box1.obj">
          <drake:declare_convex/>
        </mesh>
      </geometry>
      <origin rpy="0 0 0" xyz="0 0 0"/>
    </collision>
    <collision>
      <geometry>
        <mesh filename="package://rebot_b601_dm_description/meshes/links/collision/base_link/base_link_box2.obj">
          <drake:declare_convex/>
        </mesh>
      </geometry>
      <origin rpy="0 0 0" xyz="0 0 0"/>
    </collision>
  </link>

  <link name="link1">
    <inertial>
      <origin rpy="0 0 0" xyz="0.000113614552951627 -0.000616319527051323 0.0236476372671394"/>
      <mass value="0.16130000"/>
      <inertia ixx="0.00025207" ixy="0.00000000" ixz="-0.00002832" iyy="0.00015464" iyz="0.00000000" izz="0.00023416"/>
    </inertial>
    <visual>
      <geometry>
        <mesh filename="package://rebot_b601_dm_description/meshes/links/visual/link1.obj"/>
      </geometry>
      <origin rpy="0 0 0" xyz="0 0 0"/>
      <material name="Silver"/>
    </visual>
    <collision>
      <geometry>
        <mesh filename="package://rebot_b601_dm_description/meshes/links/collision/link1/link1_box1.obj">
          <drake:declare_convex/>
        </mesh>
      </geometry>
      <origin rpy="0 0 0" xyz="0 0 0"/>
    </collision>
    <collision>
      <geometry>
        <mesh filename="package://rebot_b601_dm_description/meshes/links/collision/link1/link1_box2.obj">
          <drake:declare_convex/>
        </mesh>
      </geometry>
      <origin rpy="0 0 0" xyz="0 0 0"/>
    </collision>
    <collision>
      <geometry>
        <mesh filename="package://rebot_b601_dm_description/meshes/links/collision/link1/link1_box3.obj">
          <drake:declare_convex/>
        </mesh>
      </geometry>
      <origin rpy="0 0 0" xyz="0 0 0"/>
    </collision>
    <collision>
      <geometry>
        <mesh filename="package://rebot_b601_dm_description/meshes/links/collision/link1/link1_box4.obj">
          <drake:declare_convex/>
        </mesh>
      </geometry>
      <origin rpy="0 0 0" xyz="0 0 0"/>
    </collision>
  </link>

  <joint name="joint1" type="revolute">
    <origin rpy="0 0 0" xyz="-8.416E-05 0 0.08465"/>
    <parent link="base_link"/>
    <child link="link1"/>
    <axis xyz="0 0 1"/>
    <limit effort="27" lower="-2.8" upper="2.8" velocity="50"/>
    <dynamics damping="1.0"/>
  </joint>

  <link name="link2">
    <inertial>
      <origin rpy="0 0 0" xyz="-0.13225622308888 -0.0030617036386309 -0.0308306967030205"/>
      <mass value="1.32660000"/>
      <inertia ixx="0.00073374" ixy="-0.00000043" ixz="0.00000851" iyy="0.01255987" iyz="0.00000128" izz="0.01281387"/>
    </inertial>
    <visual>
      <geometry>
        <mesh filename="package://rebot_b601_dm_description/meshes/links/visual/link2.obj"/>
      </geometry>
      <origin rpy="0 0 0" xyz="0 0 0"/>
      <material name="Silver"/>
    </visual>
    <collision>
      <geometry>
        <mesh filename="package://rebot_b601_dm_description/meshes/links/collision/link2/link2_box1.obj">
          <drake:declare_convex/>
        </mesh>
      </geometry>
      <origin rpy="0 0 0" xyz="0 0 0"/>
    </collision>
    <collision>
      <geometry>
        <mesh filename="package://rebot_b601_dm_description/meshes/links/collision/link2/link2_box2.obj">
          <drake:declare_convex/>
        </mesh>
      </geometry>
      <origin rpy="0 0 0" xyz="0 0 0"/>
    </collision>
    <collision>
      <geometry>
        <mesh filename="package://rebot_b601_dm_description/meshes/links/collision/link2/link2_box3.obj">
          <drake:declare_convex/>
        </mesh>
      </geometry>
      <origin rpy="0 0 0" xyz="0 0 0"/>
    </collision>
  </link>

  <joint name="joint2" type="revolute">
    <origin rpy="-1.5708 0 0" xyz="0.020084 0.031625 0.05555"/>
    <parent link="link1"/>
    <child link="link2"/>
    <axis xyz="0 0 -1"/>
    <limit effort="27" lower="-3.14" upper="0" velocity="50"/>
    <dynamics damping="1.0"/>
  </joint>

  <link name="link3">
    <inertial>
      <origin rpy="0 0 0" xyz="0.121040035791843 -0.0536211076627949 -0.0310137854608077"/>
      <mass value="0.83530000"/>
      <inertia ixx="0.00046807" ixy="-0.00003456" ixz="-0.00004260" iyy="0.00632695" iyz="0.00000006" izz="0.00648221"/>
    </inertial>
    <visual>
      <geometry>
        <mesh filename="package://rebot_b601_dm_description/meshes/links/visual/link3.obj"/>
      </geometry>
      <origin rpy="0 0 0" xyz="0 0 0"/>
      <material name="Silver"/>
    </visual>
    <collision>
      <geometry>
        <mesh filename="package://rebot_b601_dm_description/meshes/links/collision/link3/link3_box1.obj">
          <drake:declare_convex/>
        </mesh>
      </geometry>
      <origin rpy="0 0 0" xyz="0 0 0"/>
    </collision>
    <collision>
      <geometry>
        <mesh filename="package://rebot_b601_dm_description/meshes/links/collision/link3/link3_box2.obj">
          <drake:declare_convex/>
        </mesh>
      </geometry>
      <origin rpy="0 0 0" xyz="0 0 0"/>
    </collision>
    <collision>
      <geometry>
        <mesh filename="package://rebot_b601_dm_description/meshes/links/collision/link3/link3_box3.obj">
          <drake:declare_convex/>
        </mesh>
      </geometry>
      <origin rpy="0 0 0" xyz="0 0 0"/>
    </collision>
    <collision>
      <geometry>
        <mesh filename="package://rebot_b601_dm_description/meshes/links/collision/link3/link3_box4.obj">
          <drake:declare_convex/>
        </mesh>
      </geometry>
      <origin rpy="0 0 0" xyz="0 0 0"/>
    </collision>
  </link>

  <joint name="joint3" type="revolute">
    <origin rpy="0 0 0" xyz="-0.264 0 0"/>
    <parent link="link2"/>
    <child link="link3"/>
    <axis xyz="0 0 1"/>
    <limit effort="27" lower="-3.14" upper="0" velocity="50"/>
    <dynamics damping="1.0"/>
  </joint>

  <link name="link4">
    <inertial>
      <origin rpy="0 0 0" xyz="0.0608200956293136 -0.0511711906613122 -0.030299458623927"/>
      <mass value="0.52000000"/>
      <inertia ixx="0.00045986" ixy="0.00024219" ixz="-0.00000672" iyy="0.00075258" iyz="-0.00000535" izz="0.00066742"/>
    </inertial>
    <visual>
      <geometry>
        <mesh filename="package://rebot_b601_dm_description/meshes/links/visual/link4.obj"/>
      </geometry>
      <origin rpy="0 0 0" xyz="0 0 0"/>
      <material name="Silver"/>
    </visual>
    <collision>
      <geometry>
        <mesh filename="package://rebot_b601_dm_description/meshes/links/collision/link4/link4_box1.obj">
          <drake:declare_convex/>
        </mesh>
      </geometry>
      <origin rpy="0 0 0" xyz="0 0 0"/>
    </collision>
    <collision>
      <geometry>
        <mesh filename="package://rebot_b601_dm_description/meshes/links/collision/link4/link4_box2.obj">
          <drake:declare_convex/>
        </mesh>
      </geometry>
      <origin rpy="0 0 0" xyz="0 0 0"/>
    </collision>
    <collision>
      <geometry>
        <mesh filename="package://rebot_b601_dm_description/meshes/links/collision/link4/link4_box3.obj">
          <drake:declare_convex/>
        </mesh>
      </geometry>
      <origin rpy="0 0 0" xyz="0 0 0"/>
    </collision>
  </link>

  <joint name="joint4" type="revolute">
    <origin rpy="0 0 0" xyz="0.2426 -0.054 -0.001625"/>
    <parent link="link3"/>
    <child link="link4"/>
    <axis xyz="0 0 1"/>
    <limit effort="7" lower="-1.87" upper="1.57" velocity="200"/>
    <dynamics damping="1.0"/>
  </joint>

  <link name="link5">
    <inertial>
      <origin rpy="0 0 0" xyz="-0.00502802058982517 1.73866206692364E-06 0.0386233236326755"/>
      <mass value="0.38300000"/>
      <inertia ixx="0.00019772" ixy="-0.00000062" ixz="-0.00002426" iyy="0.00021737" iyz="0.00000002" izz="0.00017191"/>
    </inertial>
    <visual>
      <geometry>
        <mesh filename="package://rebot_b601_dm_description/meshes/links/visual/link5.obj"/>
      </geometry>
      <origin rpy="0 0 0" xyz="0 0 0"/>
      <material name="Black"/>
    </visual>
    <collision>
      <geometry>
        <mesh filename="package://rebot_b601_dm_description/meshes/links/collision/link5/link5_box1.obj">
          <drake:declare_convex/>
        </mesh>
      </geometry>
      <origin rpy="0 0 0" xyz="0 0 0"/>
    </collision>
    <collision>
      <geometry>
        <mesh filename="package://rebot_b601_dm_description/meshes/links/collision/link5/link5_box2.obj">
          <drake:declare_convex/>
        </mesh>
      </geometry>
      <origin rpy="0 0 0" xyz="0 0 0"/>
    </collision>
    <collision>
      <geometry>
        <mesh filename="package://rebot_b601_dm_description/meshes/links/collision/link5/link5_box3.obj">
          <drake:declare_convex/>
        </mesh>
      </geometry>
      <origin rpy="0 0 0" xyz="0 0 0"/>
    </collision>
    <collision>
      <geometry>
        <mesh filename="package://rebot_b601_dm_description/meshes/links/collision/link5/link5_box4.obj">
          <drake:declare_convex/>
        </mesh>
      </geometry>
      <origin rpy="0 0 0" xyz="0 0 0"/>
    </collision>
    <collision>
      <geometry>
        <mesh filename="package://rebot_b601_dm_description/meshes/links/collision/link5/link5_box5.obj">
          <drake:declare_convex/>
        </mesh>
      </geometry>
      <origin rpy="0 0 0" xyz="0 0 0"/>
    </collision>
  </link>

  <joint name="joint5" type="revolute">
    <origin rpy="-1.5708 0 0" xyz="0.078308 -0.0375 -0.03"/>
    <parent link="link4"/>
    <child link="link5"/>
    <axis xyz="0 0 1"/>
    <limit effort="7" lower="-1.57" upper="1.57" velocity="200"/>
    <dynamics damping="1.0"/>
  </joint>

  <link name="link6">
    <inertial>
      <origin rpy="0 0 0" xyz="3.76418727127126E-06 -0.000100908819946677 0.0253308606425965"/>
      <mass value="0.36630000"/>
      <inertia ixx="0.00015554" ixy="-0.00000" ixz="-0.00000" iyy="0.00015554" iyz="-0.0000" izz="0.00013966"/>
    </inertial>
    <visual>
      <geometry>
        <mesh filename="package://rebot_b601_dm_description/meshes/links/visual/link6.obj"/>
      </geometry>
      <origin rpy="0 0 0" xyz="0 0 0"/>
      <material name="Silver"/>
    </visual>
    <collision>
      <geometry>
        <mesh filename="package://rebot_b601_dm_description/meshes/links/collision/link6/link6_cylinder1.obj">
          <drake:declare_convex/>
        </mesh>
      </geometry>
      <origin rpy="0 0 0" xyz="0 0 0"/>
    </collision>
  </link>

  <joint name="joint6" type="revolute">
    <origin rpy="0 1.5708 0" xyz="0.023692 0 0.04"/>
    <parent link="link5"/>
    <child link="link6"/>
    <axis xyz="0 0 1"/>
    <limit effort="7" lower="-3.14" upper="3.14" velocity="200"/>
    <dynamics damping="1.0"/>
  </joint>

  <link name="gripper_link">
    <inertial>
      <origin rpy="0 0 0" xyz="-0.11400456131826 7.30809328589541E-05 -8.098254686284E-08"/>
      <mass value="0.36534420980225685"/>
      <inertia ixx="0.000467000783810404" ixy="-5.578307361665363e-07" ixz="-1.2155508679996518e-09" iyy="0.0001175784085605226" iyz="-2.3209457812342875e-08" izz="0.00041239555261615214"/>
    </inertial>
    <visual>
      <geometry>
        <mesh filename="package://rebot_b601_dm_description/meshes/gripper/visual/gripper_link.obj"/>
      </geometry>
      <origin rpy="0 0 0" xyz="0 0 0"/>
      <material name="Black"/>
    </visual>
    <collision>
      <geometry>
        <mesh filename="package://rebot_b601_dm_description/meshes/gripper/collision/gripper_link/gripper_link_box1.obj">
          <drake:declare_convex/>
        </mesh>
      </geometry>
      <origin rpy="0 0 0" xyz="0 0 0"/>
    </collision>
    <collision>
      <geometry>
        <mesh filename="package://rebot_b601_dm_description/meshes/gripper/collision/gripper_link/gripper_link_cylinder1.obj">
          <drake:declare_convex/>
        </mesh>
      </geometry>
      <origin rpy="0 0 0" xyz="0 0 0"/>
    </collision>
    <collision>
      <geometry>
        <mesh filename="package://rebot_b601_dm_description/meshes/gripper/collision/gripper_link/gripper_link_box2.obj">
          <drake:declare_convex/>
        </mesh>
      </geometry>
      <origin rpy="0 0 0" xyz="0 0 0"/>
    </collision>
  </link>

  <joint name="gripper_joint" type="fixed">
    <origin rpy="0 -1.5708 0" xyz="0 0 0.15971"/>
    <parent link="link6"/>
    <child link="gripper_link"/>
  </joint>

  <link name="gripper_left">
    <inertial>
      <origin rpy="0 0 0" xyz="0.00937154605945142 -0.0183514409006279 -0.00213050813223617"/>
      <mass value="0.0423278952416158"/>
      <inertia ixx="9.68819007445228E-06" ixy="-1.14547785891207E-06" ixz="1.82410432419993E-08" iyy="9.7195653452821E-06" iyz="1.20737618180169E-07" izz="1.13638462227589E-05"/>
    </inertial>
    <visual>
      <geometry>
        <mesh filename="package://rebot_b601_dm_description/meshes/gripper/visual/gripper_left.obj"/>
      </geometry>
      <origin rpy="0 0 0" xyz="0 0 0"/>
      <material name="NeonGreen"/>
    </visual>
    <collision>
      <geometry>
        <mesh filename="package://rebot_b601_dm_description/meshes/gripper/collision/gripper_left/gripper_left_box1.obj">
          <drake:declare_convex/>
        </mesh>
      </geometry>
      <origin rpy="0 0 0" xyz="0 0 0"/>
    </collision>
    <collision>
      <geometry>
        <mesh filename="package://rebot_b601_dm_description/meshes/gripper/collision/gripper_left/gripper_left_box2.obj">
          <drake:declare_convex/>
        </mesh>
      </geometry>
      <origin rpy="0 0 0" xyz="0 0 0"/>
    </collision>
    <collision>
      <geometry>
        <mesh filename="package://rebot_b601_dm_description/meshes/gripper/collision/gripper_left/gripper_left_box3.obj">
          <drake:declare_convex/>
        </mesh>
      </geometry>
      <origin rpy="0 0 0" xyz="0 0 0"/>
    </collision>
    <collision>
      <geometry>
        <mesh filename="package://rebot_b601_dm_description/meshes/gripper/collision/gripper_left/gripper_left_box4.obj">
          <drake:declare_convex/>
        </mesh>
      </geometry>
      <origin rpy="0 0 0" xyz="0 0 0"/>
    </collision>
    <collision>
      <geometry>
        <mesh filename="package://rebot_b601_dm_description/meshes/gripper/collision/gripper_left/gripper_left_box5.obj">
          <drake:declare_convex/>
        </mesh>
      </geometry>
      <origin rpy="0 0 0" xyz="0 0 0"/>
    </collision>
  </link>

  <joint name="gripper_joint1" type="prismatic">
    <origin rpy="0 0 -1.5708" xyz="-0.042091 2.7531E-05 -1.3031E-05"/>
    <parent link="gripper_link"/>
    <child link="gripper_left"/>
    <axis xyz="1 0 0"/>
    <limit effort="100" lower="0" upper="0.0715" velocity="15"/>
  </joint>

  <link name="gripper_right">
    <inertial>
      <origin rpy="0 0 0" xyz="0.00937154599936671 0.0183514410059713 0.00213050822993754"/>
      <mass value="0.0423278949561274"/>
      <inertia ixx="9.68819002375832E-06" ixy="1.14547786360874E-06" ixz="-1.82410118281856E-08" iyy="9.7195652747221E-06" iyz="1.20737613592695E-07" izz="1.13638461944347E-05"/>
    </inertial>
    <visual>
      <geometry>
        <mesh filename="package://rebot_b601_dm_description/meshes/gripper/visual/gripper_right.obj"/>
      </geometry>
      <origin rpy="0 0 0" xyz="0 0 0"/>
      <material name="NeonGreen"/>
    </visual>
    <collision>
      <geometry>
        <mesh filename="package://rebot_b601_dm_description/meshes/gripper/collision/gripper_right/gripper_right_box1.obj">
          <drake:declare_convex/>
        </mesh>
      </geometry>
      <origin rpy="0 0 0" xyz="0 0 0"/>
    </collision>
    <collision>
      <geometry>
        <mesh filename="package://rebot_b601_dm_description/meshes/gripper/collision/gripper_right/gripper_right_box2.obj">
          <drake:declare_convex/>
        </mesh>
      </geometry>
      <origin rpy="0 0 0" xyz="0 0 0"/>
    </collision>
    <collision>
      <geometry>
        <mesh filename="package://rebot_b601_dm_description/meshes/gripper/collision/gripper_right/gripper_right_box3.obj">
          <drake:declare_convex/>
        </mesh>
      </geometry>
      <origin rpy="0 0 0" xyz="0 0 0"/>
    </collision>
    <collision>
      <geometry>
        <mesh filename="package://rebot_b601_dm_description/meshes/gripper/collision/gripper_right/gripper_right_box4.obj">
          <drake:declare_convex/>
        </mesh>
      </geometry>
      <origin rpy="0 0 0" xyz="0 0 0"/>
    </collision>
    <collision>
      <geometry>
        <mesh filename="package://rebot_b601_dm_description/meshes/gripper/collision/gripper_right/gripper_right_box5.obj">
          <drake:declare_convex/>
        </mesh>
      </geometry>
      <origin rpy="0 0 0" xyz="0 0 0"/>
    </collision>
  </link>

  <joint name="gripper_joint2" type="prismatic">
    <origin rpy="0 0 1.5708" xyz="-0.042091 -2.7531E-05 1.3031E-05"/>
    <parent link="gripper_link"/>
    <child link="gripper_right"/>
    <axis xyz="1 0 0"/>
    <limit effort="100" lower="0" upper="0.0715" velocity="15"/>
  </joint>

  <!--
  TCP reference frame for FK / IK. The gripper fingertips meet exactly on the link6 z axis at
  z = 0.15971 (the gripper_link frame origin) when the gripper is closed, so the tip frame sits
  there with the same orientation as link6: z is the tool approach axis, y is the finger travel
  direction.
  -->
  <link name="link_eef_tip"/>

  <joint name="joint_eef_tip" type="fixed">
    <origin rpy="0 0 0" xyz="0 0 0.15971"/>
    <parent link="link6"/>
    <child link="link_eef_tip"/>
  </joint>

  <!--
  The two fingers touch at the closed state (q = 0), so mutual finger contact is filtered out;
  objects being grasped still collide with each finger individually.
  -->
  <drake:collision_filter_group name="gripper_fingers">
    <drake:member link="gripper_left"/>
    <drake:member link="gripper_right"/>
    <drake:ignored_collision_filter_group name="gripper_fingers"/>
  </drake:collision_filter_group>

  <!--
  The link6 flange is permanently nested inside the link4 wrist bracket (their tight convex
  envelopes overlap at every joint configuration), so this pair is filtered like an adjacent
  pair. Any real flange-bracket contact would first show up as the adjacent link4-link5 pair
  hitting its joint limit.
  -->
  <drake:collision_filter_group name="wrist_bracket">
    <drake:member link="link4"/>
    <drake:ignored_collision_filter_group name="wrist_flange"/>
  </drake:collision_filter_group>
  <drake:collision_filter_group name="wrist_flange">
    <drake:member link="link6"/>
  </drake:collision_filter_group>

  <!-- Actuators -->
  <transmission name="tran1">
    <type>transmission_interface/SimpleTransmission</type>
    <joint name="joint1">
      <hardwareInterface>hardware_interface/PositionJointInterface</hardwareInterface>
    </joint>
    <actuator name="motor1">
      <hardwareInterface>hardware_interface/PositionJointInterface</hardwareInterface>
      <mechanicalReduction>1</mechanicalReduction>
      <drake:gear_ratio value="40.0"/>
    </actuator>
  </transmission>

  <transmission name="tran2">
    <type>transmission_interface/SimpleTransmission</type>
    <joint name="joint2">
      <hardwareInterface>hardware_interface/PositionJointInterface</hardwareInterface>
    </joint>
    <actuator name="motor2">
      <hardwareInterface>hardware_interface/PositionJointInterface</hardwareInterface>
      <mechanicalReduction>1</mechanicalReduction>
      <drake:gear_ratio value="40.0"/>
    </actuator>
  </transmission>

  <transmission name="tran3">
    <type>transmission_interface/SimpleTransmission</type>
    <joint name="joint3">
      <hardwareInterface>hardware_interface/PositionJointInterface</hardwareInterface>
    </joint>
    <actuator name="motor3">
      <hardwareInterface>hardware_interface/PositionJointInterface</hardwareInterface>
      <mechanicalReduction>1</mechanicalReduction>
      <drake:gear_ratio value="40.0"/>
    </actuator>
  </transmission>

  <transmission name="tran4">
    <type>transmission_interface/SimpleTransmission</type>
    <joint name="joint4">
      <hardwareInterface>hardware_interface/PositionJointInterface</hardwareInterface>
    </joint>
    <actuator name="motor4">
      <hardwareInterface>hardware_interface/PositionJointInterface</hardwareInterface>
      <mechanicalReduction>1</mechanicalReduction>
      <drake:gear_ratio value="10.0"/>
    </actuator>
  </transmission>

  <transmission name="tran5">
    <type>transmission_interface/SimpleTransmission</type>
    <joint name="joint5">
      <hardwareInterface>hardware_interface/PositionJointInterface</hardwareInterface>
    </joint>
    <actuator name="motor5">
      <hardwareInterface>hardware_interface/PositionJointInterface</hardwareInterface>
      <mechanicalReduction>1</mechanicalReduction>
      <drake:gear_ratio value="10.0"/>
    </actuator>
  </transmission>

  <transmission name="tran6">
    <type>transmission_interface/SimpleTransmission</type>
    <joint name="joint6">
      <hardwareInterface>hardware_interface/PositionJointInterface</hardwareInterface>
    </joint>
    <actuator name="motor6">
      <hardwareInterface>hardware_interface/PositionJointInterface</hardwareInterface>
      <mechanicalReduction>1</mechanicalReduction>
      <drake:gear_ratio value="10.0"/>
    </actuator>
  </transmission>

  <transmission name="tran7">
    <type>transmission_interface/SimpleTransmission</type>
    <joint name="gripper_joint1">
      <hardwareInterface>hardware_interface/PositionJointInterface</hardwareInterface>
    </joint>
    <actuator name="motor7">
      <hardwareInterface>hardware_interface/PositionJointInterface</hardwareInterface>
      <mechanicalReduction>1</mechanicalReduction>
    </actuator>
  </transmission>

  <transmission name="tran8">
    <type>transmission_interface/SimpleTransmission</type>
    <joint name="gripper_joint2">
      <hardwareInterface>hardware_interface/PositionJointInterface</hardwareInterface>
    </joint>
    <actuator name="motor8">
      <hardwareInterface>hardware_interface/PositionJointInterface</hardwareInterface>
      <mechanicalReduction>1</mechanicalReduction>
    </actuator>
  </transmission>

</robot>
