<?xml version="1.0"?>

<!--
Model of the reverse parallel gripper, without any gripper actuation.
The model will thus have 6 positions (6 joint DOF) and velocities
for a total of 12 states. This model can be used for any Drake system computation
that does not need the gripper DOF (Jacobian computation, etc.).
-->

<robot xmlns:drake="http://drake.mit.edu" name="lite6_robot_with_unactuated_reverse_parallel_gripper">

  <material name="Black">
    <color rgba="0.0 0.0 0.0 1.0"/>
  </material>
  <material name="Red">
    <color rgba="0.8 0.0 0.0 1.0"/>
  </material>
  <material name="White">
    <color rgba="1.0 1.0 1.0 1.0"/>
  </material>
  <material name="Silver">
    <color rgba="0.753 0.753 0.753 1.0"/>
  </material>
  <material name="DarkSilver">
    <color rgba="0.653 0.653 0.653 1.0"/>
  </material>

  <link name="link_base">
    <inertial>
      <origin rpy="0 0 0" xyz="-0.00829544579053192 3.26357432323433E-05 0.0631194584987089"/>
      <mass value="1.65393501783165"/>
      <inertia ixx="0" ixy="0" ixz="0" iyy="0" iyz="0" izz="0"/>
    </inertial>
    <visual>
      <geometry>
        <mesh filename="package://lite6_description/meshes/links/visual/link_base.obj"/>
      </geometry>
      <origin rpy="0 0 0" xyz="0 0 0"/>
      <material name="White"/>
    </visual>
    <collision>
      <geometry>
        <mesh filename="package://lite6_description/meshes/links/collision/link_base/link_base_cylinder1.obj">
          <drake:declare_convex/>
        </mesh>
      </geometry>
      <origin rpy="0 0 0" xyz="0 0 0"/>
    </collision>
    <collision>
      <geometry>
        <mesh filename="package://lite6_description/meshes/links/collision/link_base/link_base_cylinder2.obj">
          <drake:declare_convex/>
        </mesh>
      </geometry>
      <origin rpy="0 0 0" xyz="0 0 0"/>
    </collision>

  </link>
  <link name="link1">
    <inertial>
      <origin rpy="0 0 0" xyz="-0.00036 0.04195 -0.0025"/>
      <mass value="1.411"/>
      <inertia ixx="0.0014516400000000001" ixy="-1.24e-05" ixz="6.7e-06" iyy="0.0008872999999999999" iyz="-0.0001255" izz="0.00131993"/>
    </inertial>
    <visual>
      <geometry>
        <mesh filename="package://lite6_description/meshes/links/visual/link1.obj"/>
      </geometry>
      <origin rpy="0 0 0" xyz="0 0 0"/>
      <material name="DarkSilver"/>
    </visual>
    <collision>
      <geometry>
        <mesh filename="package://lite6_description/meshes/links/collision/link1/link1_cylinder1.obj">
          <drake:declare_convex/>
        </mesh>
      </geometry>
      <origin rpy="0 0 0" xyz="0 0 0"/>
    </collision>
    <collision>
      <geometry>
        <mesh filename="package://lite6_description/meshes/links/collision/link1/link1_cylinder2.obj">
          <drake:declare_convex/>
        </mesh>
      </geometry>
      <origin rpy="0 0 0" xyz="0 0 0"/>
    </collision>
  </link>

  <joint name="joint1" type="revolute">
    <origin rpy="0 0 0" xyz="0 0 0.2435"/>
    <parent link="link_base"/>
    <child link="link1"/>
    <axis xyz="0 0 1"/>
    <limit effort="50.0" lower="-6.283185307179586" upper="6.283185307179586" velocity="3.14"/>
    <dynamics damping="1.0"/>
  </joint>

  <link name="link2">
    <inertial>
      <origin rpy="0 0 0" xyz="0.179 0.0 0.0584"/>
      <mass value="1.34"/>
      <inertia ixx="0.0015854" ixy="6.766e-06" ixz="0.00115136" iyy="0.0056097" iyz="-1.1399999999999999e-06" izz="0.00485"/>
    </inertial>
    <visual>
      <geometry>
        <mesh filename="package://lite6_description/meshes/links/visual/link2.obj"/>
      </geometry>
      <origin rpy="0 0 0" xyz="0 0 0"/>
      <material name="White"/>
    </visual>
    <collision>
      <geometry>
        <mesh filename="package://lite6_description/meshes/links/collision/link2/link2_cylinder1.obj">
          <drake:declare_convex/>
        </mesh>
      </geometry>
      <origin rpy="0 0 0" xyz="0 0 0"/>
    </collision>
    <collision>
      <geometry>
        <mesh filename="package://lite6_description/meshes/links/collision/link2/link2_cylinder2.obj">
          <drake:declare_convex/>
        </mesh>
      </geometry>
      <origin rpy="0 0 0" xyz="0 0 0"/>
    </collision>
    <collision>
      <geometry>
        <mesh filename="package://lite6_description/meshes/links/collision/link2/link2_box1.obj">
          <drake:declare_convex/>
        </mesh>
      </geometry>
      <origin rpy="0 0 0" xyz="0 0 0"/>
    </collision>
  </link>

  <joint name="joint2" type="revolute">
    <origin rpy="1.5708 -1.5708 3.1416" xyz="0 0 0"/>
    <parent link="link1"/>
    <child link="link2"/>
    <axis xyz="0 0 1"/>
    <limit effort="50.0" lower="-2.61799" upper="2.61799" velocity="3.14"/>
    <dynamics damping="1.0"/>
  </joint>

  <link name="link3">
    <inertial>
      <origin rpy="0 0 0" xyz="0.072 -0.0357 -0.001"/>
      <mass value="0.953"/>
      <inertia ixx="0.0008861" ixy="0.00039286999999999997" ixz="-7.065999999999999e-05" iyy="0.0015784999999999998" iyz="2.4449999999999998e-05" izz="0.00184677"/>
    </inertial>
    <visual>
      <geometry>
        <mesh filename="package://lite6_description/meshes/links/visual/link3.obj"/>
      </geometry>
      <origin rpy="0 0 0" xyz="0 0 0"/>
      <material name="DarkSilver"/>
    </visual>
    <collision>
      <geometry>
        <mesh filename="package://lite6_description/meshes/links/collision/link3/link3_cylinder1.obj">
          <drake:declare_convex/>
        </mesh>
      </geometry>
      <origin rpy="0 0 0" xyz="0 0 0"/>
    </collision>
    <collision>
      <geometry>
        <mesh filename="package://lite6_description/meshes/links/collision/link3/link3_cylinder2.obj">
          <drake:declare_convex/>
        </mesh>
      </geometry>
      <origin rpy="0 0 0" xyz="0 0 0"/>
    </collision>
    <collision>
      <geometry>
        <mesh filename="package://lite6_description/meshes/links/collision/link3/link3_box1.obj">
          <drake:declare_convex/>
        </mesh>
      </geometry>
      <origin rpy="0 0 0" xyz="0 0 0"/>
    </collision>
  </link>

  <joint name="joint3" type="revolute">
    <origin rpy="-3.1416 0 1.5708" xyz="0.2002 0 0"/>
    <parent link="link2"/>
    <child link="link3"/>
    <axis xyz="0 0 1"/>
    <limit effort="32.0" lower="-0.061087" upper="5.235988" velocity="3.14"/>
    <dynamics damping="1.0"/>
  </joint>

  <link name="link4">
    <inertial>
      <origin rpy="0 0 0" xyz="-0.002 -0.0285 -0.0813"/>
      <mass value="1.284"/>
      <inertia ixx="0.003705" ixy="2e-06" ixz="-7.17e-06" iyy="0.0030455" iyz="0.00093188" izz="0.0015412999999999998"/>
    </inertial>
    <visual>
      <geometry>
        <mesh filename="package://lite6_description/meshes/links/visual/link4.obj"/>
      </geometry>
      <origin rpy="0 0 0" xyz="0 0 0"/>
      <material name="White"/>
    </visual>
    <collision>
      <geometry>
        <mesh filename="package://lite6_description/meshes/links/collision/link4/link4_cylinder1.obj">
          <drake:declare_convex/>
        </mesh>
      </geometry>
      <origin rpy="0 0 0" xyz="0 0 0"/>
    </collision>
    <collision>
      <geometry>
        <mesh filename="package://lite6_description/meshes/links/collision/link4/link4_cylinder2.obj">
          <drake:declare_convex/>
        </mesh>
      </geometry>
      <origin rpy="0 0 0" xyz="0 0 0"/>
    </collision>
    <collision>
      <geometry>
        <mesh filename="package://lite6_description/meshes/links/collision/link4/link4_cylinder3.obj">
          <drake:declare_convex/>
        </mesh>
      </geometry>
      <origin rpy="0 0 0" xyz="0 0 0"/>
    </collision>
    <collision>
      <geometry>
        <mesh filename="package://lite6_description/meshes/links/collision/link4/link4_box1.obj">
          <drake:declare_convex/>
        </mesh>
      </geometry>
      <origin rpy="0 0 0" xyz="0 0 0"/>
    </collision>
  </link>

  <joint name="joint4" type="revolute">
    <origin rpy="1.5708 0 0" xyz="0.087 -0.22761 0"/>
    <parent link="link3"/>
    <child link="link4"/>
    <axis xyz="0 0 1"/>
    <limit effort="32.0" lower="-6.283185307179586" upper="6.283185307179586" velocity="3.14"/>
    <dynamics damping="1.0"/>
  </joint>

  <link name="link5">
    <inertial>
      <origin rpy="0 0 0" xyz="0.0 0.01 0.0019"/>
      <mass value="0.804"/>
      <inertia ixx="0.0005667999999999999" ixy="-6e-07" ixz="5.299999999999999e-06" iyy="0.0005076999999999999" iyz="4.8e-07" izz="0.00053"/>
    </inertial>
    <visual>
      <geometry>
        <mesh filename="package://lite6_description/meshes/links/visual/link5.obj"/>
      </geometry>
      <origin rpy="0 0 0" xyz="0 0 0"/>
      <material name="White"/>
    </visual>
    <collision>
      <geometry>
        <mesh filename="package://lite6_description/meshes/links/collision/link5/link5_cylinder1.obj">
          <drake:declare_convex/>
        </mesh>
      </geometry>
      <origin rpy="0 0 0" xyz="0 0 0"/>
    </collision>
    <collision>
      <geometry>
        <mesh filename="package://lite6_description/meshes/links/collision/link5/link5_cylinder2.obj">
          <drake:declare_convex/>
        </mesh>
      </geometry>
      <origin rpy="0 0 0" xyz="0 0 0"/>
    </collision>
  </link>

  <joint name="joint5" type="revolute">
    <origin rpy="1.5708 0 0" xyz="0 0 0"/>
    <parent link="link4"/>
    <child link="link5"/>
    <axis xyz="0 0 1"/>
    <limit effort="32.0" lower="-2.1642" upper="2.1642" velocity="3.14"/>
    <dynamics damping="1.0"/>
  </joint>

  <link name="link6">
    <inertial>
      <origin rpy="0 0 0" xyz="0.0 -0.00194 -0.0102"/>
      <mass value="0.13"/>
      <inertia ixx="7.726e-05" ixy="-1e-06" ixz="-4e-07" iyy="8.5665e-05" iyz="6e-07" izz="0.00014813999999999997"/>
    </inertial>
    <visual>
      <geometry>
        <mesh filename="package://lite6_description/meshes/links/visual/link6.obj"/>
      </geometry>
      <origin rpy="0 0 0" xyz="0 0 0"/>
      <material name="DarkSilver"/>
    </visual>
    <collision>
      <geometry>
        <mesh filename="package://lite6_description/meshes/links/collision/link6/link6_cylinder1.obj">
          <drake:declare_convex/>
        </mesh>
      </geometry>
      <origin rpy="0 0 0" xyz="0 0 0"/>
    </collision>
  </link>

  <joint name="joint6" type="revolute">
    <origin rpy="-1.5708 0 0" xyz="0 0.0625 0"/>
    <parent link="link5"/>
    <child link="link6"/>
    <axis xyz="0 0 1"/>
    <limit effort="20.0" lower="-6.283185307179586" upper="6.283185307179586" velocity="3.14"/>
    <dynamics damping="1.0"/>
  </joint>

  <link name="lite6_reverse_parallel_gripper_link">
    <inertial>
      <origin rpy="0 0 0" xyz="0.0 0.0 0.030"/>
      <mass value="0.28"/>
      <inertia ixx="0.00047106" ixy="3.9292E-07" ixz="2.6537E-06" iyy="0.00033072" iyz="-1.0975E-05" izz="0.00025642"/>
    </inertial>
    <visual>
      <geometry>
        <mesh filename="package://lite6_description/meshes/gripper/visual/parallel_gripper_base.obj"/>
      </geometry>
      <origin rpy="0 0 0" xyz="0 0 0"/>
      <material name="White"/>
    </visual>
    <collision>
      <geometry>
        <mesh filename="package://lite6_description/meshes/gripper/collision/parallel_gripper/parallel_gripper_cylinder1.obj">
          <drake:declare_convex/>
        </mesh>
      </geometry>
      <origin rpy="0 0 0" xyz="0 0 0"/>
    </collision>
    <collision>
      <geometry>
        <mesh filename="package://lite6_description/meshes/gripper/collision/parallel_gripper/parallel_gripper_ellipse1.obj">
          <drake:declare_convex/>
        </mesh>
      </geometry>
      <origin rpy="0 0 0" xyz="0 0 0"/>
    </collision>
  </link>

  <joint name="joint_gripper_connector" type="fixed">
    <parent link="link6"/>
    <child link="lite6_reverse_parallel_gripper_link"/>
    <origin rpy="0 0 0" xyz="0 0 0"/>
  </joint>

  <!--
    Designing the parallel prismatic joint actuated grippers as boxes.
    Each box is 2.5 cm tall, 2 cm wide and 0.5 cm thick.
    For the reverse configuration, when closed, the distance (gripper outer edge to edge) is 2.2 cm.
    When open, the distance is 3.8 cm (1.6 cm delta as confirmed by the robot specs)
    Note that we also have to account for the thickness of the parallel blocks when setting up the joint origins.
    Do the math.
  -->

  <link name="left_parallel_gripper_link">
    <inertial>
      <mass value = "0.005"/>
      <origin rpy="0 0 0" xyz="0 0 0.0125"/>
      <inertia ixx="0.00000027" ixy="0" ixz="0" iyy="0.000000427" iyz="0" izz="0.000000177"/>
    </inertial>
    <collision>
      <geometry>
        <box size="0.02 0.005 0.025"/>
      </geometry>
      <origin rpy="0 0 0" xyz="0 0 0.0125"/>
    </collision>
    <visual>
      <geometry>
        <box size="0.02 0.005 0.025"/>
      </geometry>
      <origin rpy="0 0 0" xyz="0 0 0.0125"/>
      <material name="Black"/>
    </visual>
  </link>

  <link name="right_parallel_gripper_link">
    <inertial>
      <mass value = "0.005"/>
      <origin rpy="0 0 0" xyz="0 0 0.0125"/>
      <inertia ixx="0.00000027" ixy="0" ixz="0" iyy="0.000000427" iyz="0" izz="0.000000177"/>
    </inertial>
    <collision>
      <geometry>
        <box size="0.02 0.005 0.025"/>
      </geometry>
      <origin rpy="0 0 0" xyz="0 0 0.0125"/>
    </collision>
    <visual>
      <geometry>
        <box size="0.02 0.005 0.025"/>
      </geometry>
      <origin rpy="0 0 0" xyz="0 0 0.0125"/>
      <material name="Black"/>
    </visual>
  </link>

  <link name="link_eef_tip"/>

  <joint name="joint_eef_tip" type="fixed">
    <origin rpy="0 0 0" xyz="0 0 0.0836"/>
    <parent link="lite6_reverse_parallel_gripper_link"/>
    <child link="link_eef_tip"/>
  </joint>

  <!-- Actuators -->
  <transmission name="tran1">
    <type>transmission_interface/SimpleTransmission</type>
    <joint name="joint1">
      <hardwareInterface>hardware_interface/PositionJointInterface</hardwareInterface>
    </joint>
    <actuator name="motor1">
      <hardwareInterface>hardware_interface/PositionJointInterface</hardwareInterface>
      <mechanicalReduction>1</mechanicalReduction>
      <drake:gear_ratio value="100.0" />
    </actuator>
  </transmission>

  <transmission name="tran2">
    <type>transmission_interface/SimpleTransmission</type>
    <joint name="joint2">
      <hardwareInterface>hardware_interface/PositionJointInterface</hardwareInterface>
    </joint>
    <actuator name="motor2">
      <hardwareInterface>hardware_interface/PositionJointInterface</hardwareInterface>
      <mechanicalReduction>1</mechanicalReduction>
      <drake:gear_ratio value="100.0" />
    </actuator>
  </transmission>

  <transmission name="tran3">
    <type>transmission_interface/SimpleTransmission</type>
    <joint name="joint3">
      <hardwareInterface>hardware_interface/PositionJointInterface</hardwareInterface>
    </joint>
    <actuator name="motor3">
      <hardwareInterface>hardware_interface/PositionJointInterface</hardwareInterface>
      <mechanicalReduction>1</mechanicalReduction>
      <drake:gear_ratio value="100.0" />
    </actuator>
  </transmission>

  <transmission name="tran4">
    <type>transmission_interface/SimpleTransmission</type>
    <joint name="joint4">
      <hardwareInterface>hardware_interface/PositionJointInterface</hardwareInterface>
    </joint>
    <actuator name="motor4">
      <hardwareInterface>hardware_interface/PositionJointInterface</hardwareInterface>
      <mechanicalReduction>1</mechanicalReduction>
      <drake:gear_ratio value="100.0" />
    </actuator>
  </transmission>

  <transmission name="tran5">
    <type>transmission_interface/SimpleTransmission</type>
    <joint name="joint5">
      <hardwareInterface>hardware_interface/PositionJointInterface</hardwareInterface>
    </joint>
    <actuator name="motor5">
      <hardwareInterface>hardware_interface/PositionJointInterface</hardwareInterface>
      <mechanicalReduction>1</mechanicalReduction>
      <drake:gear_ratio value="100.0" />
    </actuator>
  </transmission>

  <transmission name="tran6">
    <type>transmission_interface/SimpleTransmission</type>
    <joint name="joint6">
      <hardwareInterface>hardware_interface/PositionJointInterface</hardwareInterface>
    </joint>
    <actuator name="motor6">
      <hardwareInterface>hardware_interface/PositionJointInterface</hardwareInterface>
      <mechanicalReduction>1</mechanicalReduction>
      <drake:gear_ratio value="100.0" />
    </actuator>
  </transmission>

</robot>
